Workbook

Sheet Inputs
A1: AI FINANCE TOOLKIT — OWN-PRICE VALUATION ENGINE
A2: Reusable any-cap model · Worked example: enCore Energy Corp (EU)
A3: HOW TO USE — 1) Edit BLUE cells only. 2) Pick your cap bucket in the YELLOW dropdown (B21). 3) Read your answer on the OwnPrice tab. YELLOW = key levers.
A5: A. COMPANY & MARKET | C5: Source / note
A6: Company name | B6: enCore Energy Corp | C6: Swap for any stock
A7: Ticker / exchange | B7: EU (NASDAQ) | C7: Use the USD listing, not TSXV CAD line
A8: Share price ($) | B8: 1.25 | C8: VERIFY LIVE — observed $1.30–$2.05 mid-Jul 2026 (ChartMill $1.52)
A9: Shares outstanding — basic (M) | B9: 194.216 | C9: 10-Q balance sheet, 31 Mar 2026 (194,216,153)
A10: Shares outstanding — diluted (M) | B10: 204.8 | C10: Corp. presentation, 24 Mar 2026
A11: Shares used for valuation (M) | B11: =B9 | C11: Change to =B10 for a more conservative per-share NAV
A12: Market cap ($M) | B12: =B8*B11 | C12: price x shares — drives the suggested cap bucket
A13: Cash & equivalents ($M) | B13: 41.6 | C13: 10-Q, 31 Mar 2026 ($41.56M)
A14: Marketable securities ($M) | B14: 70.1 | C14: 10-Q, 31 Mar 2026 (incl. 23.8M Ur-Energy shares)
A15: Debt — face value ($M) | B15: 115 | C15: Convertible note $115M face, 5.5%, matures Aug 2030
A16: Net cash / (debt) ($M) | B16: =B13+B14-B15 | C16: Conservative: uses face value of the convertible
A19: B. CAP-SIZE ENGINE
A20: Suggested bucket (auto, from market cap) | B20: =IF(B12<E29,"Micro",IF(B12<E30,"Small",IF(B12<E31,"Mid","Large"))) | C20: Auto-classified from B12 vs thresholds in the table below
A21: SELECTED cap bucket | B21: Micro | C21: Dropdown: Micro / Small / Mid / Large — accept the suggestion or override
A22: Size premium (auto from bucket) | B22: =INDEX($F$28:$F$31,MATCH($B$21,$E$28:$E$31,0)) | C22: Kroll CRSP decile size-premium study (D10 ≈ 4.7%)
A23: Liquidity discount — bucket default | B23: =INDEX($G$28:$G$31,MATCH($B$21,$E$28:$E$31,0)) | C23: Restricted-stock / pre-IPO DLOM study ranges
A24: Liquidity discount — override (optional) | B24: 0.1 | C24: EU is exchange-listed & trades daily → ~10%, not the full 25% private-company DLOM. DELETE this cell's value to use the bucket default
A25: Liquidity discount USED | B25: =IF(ISNUMBER(B24),B24,B23) | C25: Feeds the OwnPrice haircut
E27: Calibration table (BLUE = retune to taste)
D28: Thresholds ($M) → | E28: Micro | F28: 0.045 | G28: 0.25 | H28: < $300M
E29: Small | F29: 0.025 | G29: 0.15 | H29: $300M – $2B
E30: Mid | F30: 0.01 | G30: 0.075 | H30: $2B – $10B
E31: Large | F31: 0 | G31: 0.025 | H31: > $10B
E33: Auto-classifier thresholds ($M):
A34: C. DISCOUNT RATE BUILD | E34: Micro/Small | F34: 300
A35: Risk-free rate (US 10Y) | B35: 0.0455 | C35: UST 10Y, 17 Jul 2026 | E35: Small/Mid | F35: 2000
A36: Equity risk premium | B36: 0.05 | C36: Kroll recommended US ERP (Damodaran alt: 4.45%) | E36: Mid/Large | F36: 10000
A37: Beta | B37: 1.3 | C37: Micro-cap uranium producer; set 1.0 for a steadier name
A38: Base cost of equity | B38: =B35+B37*B36 | C38: RFR + beta x ERP
A39: + Size premium | B39: =B22
A40: DISCOUNT RATE USED | B40: =B38+B22 | C40: Feeds every PV in the DCF
A42: D. TERMINAL VALUE & OPERATING LEVERS
A43: TV method | B43: Exit multiple | C43: Dropdown: 'Gordon growth' or 'Exit multiple'. Exit multiple suits a ramping miner with lumpy capex
A44: TV growth rate (Gordon) | B44: 0.02 | C44: Long-run inflation
A45: Exit EV per lb of resource ($/lb) | B45: 12 | C45: Peer-derived $10–15/lb band; also feeds the Peers leg
A46: Total resource (M lbs) | B46: 51.5 | C46: S-K 1300, 31 Dec 2025: 30.94M M&I + 20.54M inferred
...

Sheet Sensitivity
A1: URANIUM PRICE SENSITIVITY — Year-1 economics
A2: Anchors: spot $85.25/lb (15 Jul 2026) · term $91.50/lb (Kazatomprom Q1 26) · EU Q1 26 realized $67.78/lb. EU sells into legacy contracts, so model REALIZED price, not spot.
A4: Scenario | B4: Spot ($/lb) | C4: Assumed realized ($/lb) | D4: Cash cost ($/lb) | E4: Total cost ($/lb) | F4: Cash margin ($/lb) | G4: All-in margin ($/lb) | H4: Production (M lbs) | I4: Gross profit ($M)
A5: Bear | B5: 50 | C5: 55 | D5: =DCF!B7 | E5: =DCF!B8 | F5: =C5-D5 | G5: =C5-E5 | H5: =DCF!B4 | I5: =G5*H5
A6: Base (≈ current realized) | B6: 70 | C6: 68 | D6: =DCF!B7 | E6: =DCF!B8 | F6: =C6-D6 | G6: =C6-E6 | H6: =DCF!B4 | I6: =G6*H6
A7: Term-price world | B7: 90 | C7: 87 | D7: =DCF!B7 | E7: =DCF!B8 | F7: =C7-D7 | G7: =C7-E7 | H7: =DCF!B4 | I7: =G7*H7
A8: Bull | B8: 110 | C8: 105 | D8: =DCF!B7 | E8: =DCF!B8 | F8: =C8-D8 | G8: =C8-E8 | H8: =DCF!B4 | I8: =G8*H8
A10: BLUE realized prices are yours to flex. Costs & production pull live from DCF Year 1 (green).

Sheet DCF
A1: 5-YEAR DCF / NAV — enCore Energy (EU)
A2: BLUE rows = your assumptions (2027–2030 are MODELLED, not company guidance — EU cut FY26 guidance on Alta Mesa permitting). Everything else recalculates.
B3: 2026 | C3: 2027 | D3: 2028 | E3: 2029 | F3: 2030 | G3: Note
A4: Production (M lbs) | B4: 0.7 | C4: 1 | D4: 1.5 | E4: 2 | F4: 2.5 | G4: FY25 actual 0.70M; ramp to Alta Mesa 1.5M licensed, then Dewey Burdock — MODELLED
A5: Realized price ($/lb) | B5: 68 | C5: 72 | D5: 78 | E5: 84 | F5: 88 | G5: Q1 26 actual $67.78 rolling toward $91.50 term as legacy contracts expire
A6: Revenue ($M) | B6: =B4*B5 | C6: =C4*C5 | D6: =D4*D5 | E6: =E4*E5 | F6: =F4*F5
A7: Cash cost ($/lb) | B7: 35 | C7: 33 | D7: 31 | E7: 30 | F7: 30 | G7: Q1 26 actual $34.94, easing with scale
A8: Total cost ($/lb) | B8: 46 | C8: 44 | D8: 42 | E8: 41 | F8: 40 | G8: Q1 26 extracted all-in $46.43 (cash + $11.48 non-cash)
A9: Operating cost ($M) | B9: =B4*B8 | C9: =C4*C8 | D9: =D4*D8 | E9: =E4*E8 | F9: =F4*F8
A10: Gross profit ($M) | B10: =B6-B9 | C10: =C6-C9 | D10: =D6-D9 | E10: =E6-E9 | F10: =F6-F9
A11: Overhead ($M) | B11: =B6*Inputs!$B$47 | C11: =C6*Inputs!$B$47 | D11: =D6*Inputs!$B$47 | E11: =E6*Inputs!$B$47 | F11: =F6*Inputs!$B$47 | G11: % of revenue from Inputs
A12: EBITDA ($M) | B12: =B10-B11 | C12: =C10-C11 | D12: =D10-D11 | E12: =E10-E11 | F12: =F10-F11
A13: Capex ($M) | B13: 25 | C13: 30 | D13: 40 | E13: 90 | F13: 90 | G13: Sustaining $25–40M; Dewey Burdock $264M total assumed staged 2029–31 — FLEX THIS: financing exceeds current market cap
A14: Free cash flow ($M) | B14: =B12-B13 | C14: =C12-C13 | D14: =D12-D13 | E14: =E12-E13 | F14: =F12-F13
A15: Year index | B15: 1 | C15: 2 | D15: 3 | E15: 4 | F15: 5
A16: Discount factor | B16: =1/(1+Inputs!$B$40)^B15 | C16: =1/(1+Inputs!$B$40)^C15 | D16: =1/(1+Inputs!$B$40)^D15 | E16: =1/(1+Inputs!$B$40)^E15 | F16: =1/(1+Inputs!$B$40)^F15
A17: PV of FCF ($M) | B17: =B14*B16 | C17: =C14*C16 | D17: =D14*D16 | E17: =E14*E16 | F17: =F14*F16
A19: TERMINAL VALUE & NAV
A20: Normalized FCF for TV ($M) | B20: =F12-Inputs!$B$48 | G20: 2030 EBITDA less steady-state sustaining capex
A21: TV — Gordon growth ($M) | B21: =IFERROR(B20*(1+Inputs!$B$44)/(Inputs!$B$40-Inputs!$B$44),0) | G21: Guarded: returns 0 if growth ≥ discount rate
A22: TV — Exit multiple ($M) | B22: =Inputs!$B$45*Inputs!$B$46 | G22: Exit EV/lb × total resource lbs
A23: TV selected ($M) | B23: =IF(Inputs!$B$43="Gordon growth",B21,B22) | G23: Switch method on Inputs (B43)
A24: PV of terminal value ($M) | B24: =B23*F16
A25: Sum PV of FCF ($M) | B25: =SUM(B17:F17)
A26: Enterprise value ($M) | B26: =B24+B25
A27: + Cash & marketable securities ($M) | B27: =Inputs!B13+Inputs!B14
A28: − Debt, face value ($M) | B28: =Inputs!B15
A29: Equity value ($M) | B29: =B26+B27-B28
A30: NAV PER SHARE ($) | B30: =B29/Inputs!B11 | G30: → feeds OwnPrice

Sheet Peers
A1: PEER CROSS-CHECK — uranium universe (point-in-time May–Jul 2026)
A2: Producers command an EV/lb premium over developers; Cameco trades ~2.3× NAV while developers/KAP sit near or below NAV. Refresh BLUE caps before each run.
A4: Company | B4: Ticker | C4: Mkt cap ($M) | D4: Status | E4: Production / capacity | F4: Note
A5: Cameco | B5: CCJ | C5: 64500 | D5: Producer | E5: ~28M lbs/yr contracted 2026–30 | F5: Trades ~2.3× NAV; + Westinghouse 49%
A6: NexGen Energy | B6: NXE | C6: 10950 | D6: Developer | E6: 0 — Rook I / Arrow | F6: Athabasca; first ore ~late decade
A7: Uranium Energy | B7: UEC | C7: 6200 | D7: Producer (ramp) | E7: 12.1M lbs/yr licensed; small actual output | F7: Debt-free, unhedged; use ACTUAL lbs for EV/lb
A8: Denison Mines | B8: DNN | C8: 4710 | D8: Developer | E8: ~0 — Wheeler River / Phoenix | F8: Trades ≤ NAV
A9: Energy Fuels | B9: UUUU | C9: 4510 | D9: Producer | E9: 1.5–2.5M lbs 2026 guidance | F9: + rare earths
A10: Kazatomprom | B10: KAP | C10: 13500 | D10: Producer | E10: >40% of global primary output | F10: Lowest cost; Kazakh state risk; ≤ NAV
A11: Ur-Energy | B11: URG | C11: 602 | D11: Producer | E11: ISR — Lost Creek, Shirley Basin | F11: EU holds 23.8M URG shares
A12: enCore Energy | B12: EU | C12: =Inputs!B12 | D12: Producer (ramp) | E12: ~0.7M lbs/yr now; 1.5M licensed Alta Mesa | F12: Resource 51.5M lbs (M&I + inferred)
A14: PEER-IMPLIED PRICE FOR THIS STOCK
A15: EV per lb of resource applied ($/lb) | B15: =Inputs!B45 | C15: Shared lever with the TV exit multiple (Inputs B45) — one number to steer both
A16: Resource (M lbs) | B16: =Inputs!B46
A17: Implied enterprise value ($M) | B17: =B15*B16
A18: + Cash & securities − debt ($M) | B18: =Inputs!B13+Inputs!B14-Inputs!B15
A19: Implied equity value ($M) | B19: =B17+B18
A20: PEER-IMPLIED PRICE ($) | B20: =B19/Inputs!B11 | C20: → feeds OwnPrice
A22: Sanity rule: if this leg and the NAV leg diverge by more than ~2×, revisit the production ramp and cost deck before trusting the blend.

Sheet OwnPrice
A1: YOUR OWN PRICE — the answer sheet
A2: Own Price = (w1 × NAV + w2 × Peer + w3 × Analyst) × (1 − liquidity discount)
A4: 1. NAV per share (DCF) | B4: =DCF!B30
A5: 2. Peer-implied price | B5: =Peers!B20
A6: 3. Analyst target | B6: =Inputs!B51
A7: 4. Weights (NAV / Peer / Analyst) | B7: =TEXT(Inputs!B52,"0%")&" / "&TEXT(Inputs!B53,"0%")&" / "&TEXT(Inputs!B54,"0%")
A8: 5. Blended value, pre-discount | B8: =Inputs!B52*B4+Inputs!B53*B5+Inputs!B54*B6
A9: 6. Liquidity discount | B9: =Inputs!B25
A10: 7. OWN PRICE | B10: =B8*(1-B9)
A11: 8. Current market price | B11: =Inputs!B8
A12: 9. Upside / (downside) | B12: =IF(B11=0,0,B10/B11-1)
A13: 10. Verdict | B13: =IF(B12>0.25,"UNDERVALUED on your assumptions",IF(B12<-0.25,"OVERVALUED on your assumptions","ROUGHLY FAIRLY VALUED on your assumptions"))
A15: Thesis triggers to watch (from July 2026 research):
A16: 1. Alta Mesa sustaining a ~1.5M lbs/yr run-rate (permitting was the 2026 drag).
A17: 2. Dewey Burdock financing — $264M capex vs ~$295M market cap: dilution/streaming risk to per-share NAV.
A18: 3. Uranium term price holding above $90/lb as EU's legacy contracts roll off.

Sheet VersionLog
A1: VERSION LOG — snapshot every run so the method self-improves
A2: Row 5 is LIVE (formulas). To freeze a version: copy row 5, then Paste Special → Values Only onto the next empty row, and type your note.
A4: Date | B4: Bucket | C4: Discount rate | D4: Liq. discount | E4: P_NAV | F4: P_Peer | G4: P_Analyst | H4: OWN PRICE | I4: Mkt price | J4: Notes
A5: =TODAY() | B5: =Inputs!B21 | C5: =Inputs!B40 | D5: =Inputs!B25 | E5: =DCF!B30 | F5: =Peers!B20 | G5: =Inputs!B51 | H5: =OwnPrice!B10 | I5: =Inputs!B8 | J5: LIVE ROW — paste values below to log
A6: 21-Jul-26 | B6: Micro | C6: 0.1555 | D6: 0.1 | E6: 1.25 | F6: 3.17 | G6: 3.75 | H6: 2.09 | I6: 1.5 | J6: Example frozen run — first EU build; capex staged 90/90 for Dewey
