Workbook

Sheet Dashboard
A1: PORTFOLIO DASHBOARD
A2: Prices as at | B2: =Prices!$B$4 | C2: update on the Prices tab
A4: PORTFOLIO SUMMARY
A5: Total invested (GBP) | B5: =G23
A6: Current market value (GBP) | B6: =H23
A7: Unrealised P/L (GBP) | B7: =I23
A8: Unrealised P/L % | B8: =IFERROR(B7/B5,0)
A9: Realised P/L (GBP) | B9: =SUM(Transactions!$P$4:$P$63)
A10: Dividends received (GBP) | B10: =SUM(Dividends!$H$4:$H$43)
A11: Total return (GBP) | B11: =B7+B9+B10
A12: Total return % | B12: =IFERROR(B11/B5,0)
A13: Day change (GBP) | B13: ='AMZN'!$B$17+'MSFT'!$B$17+'UBER'!$B$17
A14: Day change % | B14: =IFERROR(B13/(B6-B13),0)
A15: Number of holdings | B15: =COUNTIF(A20:A22,"?*")
A16: Largest position | B16: =IFERROR(INDEX(A20:A22,MATCH(MAX(H20:H22),H20:H22,0)),"")
A18: HOLDINGS
A19: Ticker | B19: Company | C19: Sleeve | D19: Shares | E19: Avg cost (GBP) | F19: Price (GBP) | G19: Invested (GBP) | H19: Market value (GBP) | I19: Unreal. P/L (GBP) | J19: P/L % | K19: Weight | L19: Signal
A20: ='AMZN'!$B$4 | B20: ='AMZN'!$B$5 | C20: ='AMZN'!$B$6 | D20: ='AMZN'!$B$8 | E20: ='AMZN'!$B$10 | F20: ='AMZN'!$B$13 | G20: ='AMZN'!$B$9 | H20: ='AMZN'!$B$14 | I20: ='AMZN'!$B$15 | J20: ='AMZN'!$B$16 | K20: ='AMZN'!$B$19 | L20: ='AMZN'!$B$55
A21: ='MSFT'!$B$4 | B21: ='MSFT'!$B$5 | C21: ='MSFT'!$B$6 | D21: ='MSFT'!$B$8 | E21: ='MSFT'!$B$10 | F21: ='MSFT'!$B$13 | G21: ='MSFT'!$B$9 | H21: ='MSFT'!$B$14 | I21: ='MSFT'!$B$15 | J21: ='MSFT'!$B$16 | K21: ='MSFT'!$B$19 | L21: ='MSFT'!$B$55
A22: ='UBER'!$B$4 | B22: ='UBER'!$B$5 | C22: ='UBER'!$B$6 | D22: ='UBER'!$B$8 | E22: ='UBER'!$B$10 | F22: ='UBER'!$B$13 | G22: ='UBER'!$B$9 | H22: ='UBER'!$B$14 | I22: ='UBER'!$B$15 | J22: ='UBER'!$B$16 | K22: ='UBER'!$B$19 | L22: ='UBER'!$B$55
A23: TOTAL | G23: =SUM(G20:G22) | H23: =SUM(H20:H22) | I23: =SUM(I20:I22) | J23: =IFERROR(I23/G23,0) | K23: =SUM(K20:K22)
A25: Green figures are pulled live from the holding tabs. Change nothing here — edit the holding tab or the Prices tab.
A26: Weight is each position as a share of current market value, not of invested capital.

Sheet README
A1: LIVE PORTFOLIO TRACKER — how to use this workbook
A3: Built | B3: 4 August 2026, from your Never Sell pie export.
A4: Holdings in v1 | B4: AMZN, MSFT, UBER — one tab each. More sleeves get added as we refine.
A6: COLOUR LEGEND — what you may type into
A7: Yellow fill, blue text | B7: TYPE HERE. These are your inputs: live prices, EPS, targets, rules.
A8: Blue text, no fill | B8: Hardcoded input you can change (opening balances, fees).
A9: Black text | B9: Formula. Do not overtype — it will break the calculation chain.
A10: Green text | B10: Link pulling from another tab in this workbook.
A12: TAB GUIDE
A13: Dashboard | B13: Whole-portfolio totals, every holding side by side, weights, and each sell signal.
A14: Prices | B14: The price engine. Update the live price cells here and the entire workbook moves.
A15: AMZN / MSFT / UBER | B15: One tab per holding: position, valuation & EPS, sell discipline, dividends, trade history, thesis.
A16: Transactions | B16: Master trade log. Every buy and sell goes here once. Shares and average cost are calculated from it — never typed.
A17: Dividends | B17: Dividend log. Feeds income figures on the holding tabs.
A18: Sell_Rules | B18: Your default sell rules in one place. Each holding tab inherits these and can override.
A20: MAKING THE PRICES LIVE — three options, pick one
A21: 1. Stocks data type | B21: Microsoft 365. On Prices, select A7:A9, then Data > Stocks. Excel converts them to linked tickers. Then set D7 to =A7.Price and fill down. Refresh with Data > Refresh All.
A22: 2. STOCKHISTORY | B22: Microsoft 365. Put this in D7 (as a formula, not text): =STOCKHISTORY(A7,TODAY()-5,TODAY(),0,0,1) and take the last row. Recalculates on file open.
A23: 3. Manual / paste | B23: Works in every version of Excel, including web and Mac. Type or paste the price into D7:D9. Takes ten seconds and every number in the workbook updates.
A25: Note | B25: A generated .xlsx cannot ship with prices already wired to a feed — Excel only trusts a live connection you enable yourself. Options 1 and 2 take one setup step each, then run themselves.
A27: ASSUMPTIONS AND SOURCES — read before trusting a number
A28: Shares, invested, value | B28: Your Trading 212 Never Sell pie export, Never-sell-2026-08-04T11-15-05.211Z.csv.
A29: Opening prices (USD) | B29: Derived: your GBP value per share x GBP/USD 1.34499. Not a feed print — replace with a live price on the Prices tab.
A30: GBP/USD 1.34499 | B30: FMP forex quote GBPUSD, 4 August 2026.
A31: EPS, forward EPS, analyst target | B31: LEFT BLANK ON PURPOSE. I will not invent company financials. Fill from the latest 10-Q or your broker's research tab — every valuation cell below them lights up the moment you do.
A32: 52-week high / low | B32: Blank. Fill on the Prices tab — the trailing stop depends on the 52w high.
A33: Sell rules | B33: Defaults on Sell_Rules are placeholders I chose, not advice. Set them to your own.
A34: Fees | B34: Assumed zero on the opening rows. Add real fees per trade in Transactions column I.
A35: Dividends | B35: AMZN, MSFT and UBER: only MSFT currently pays one. Log actual payments in Dividends.
A37: Not financial advice. Figures are only as good as the inputs you keep current.

Sheet Prices
A1: PRICE ENGINE — update the yellow cells and the whole workbook moves
A3: GBP/USD rate | B3: 1.34499 | C3: <- every USD figure is converted at this rate
A4: Prices as at | B4: 2026-08-04 | C4: <- stamp the date/time you last refreshed
A6: Ticker | B6: Company | C6: Ccy | D6: Live price | E6: Prev close | F6: Day chg | G6: Day chg % | H6: 52w high | I6: 52w low | J6: % off high | K6: EPS TTM | L6: EPS fwd | M6: P/E TTM | N6: Fwd P/E | O6: Analyst target | P6: Target upside | Q6: Price (GBP)
A7: AMZN | B7: Amazon.com, Inc. | C7: USD | D7: 277.4734 | F7: =IF(E7="","",D7-E7) | G7: =IFERROR(F7/E7,"") | J7: =IFERROR(D7/H7-1,"") | M7: =IFERROR(D7/K7,"") | N7: =IFERROR(D7/L7,"") | P7: =IFERROR(O7/D7-1,"") | Q7: =IFERROR(IF(C7="USD",D7/$B$3,D7),"")
A8: MSFT | B8: Microsoft Corporation | C8: USD | D8: 477.2864 | F8: =IF(E8="","",D8-E8) | G8: =IFERROR(F8/E8,"") | J8: =IFERROR(D8/H8-1,"") | M8: =IFERROR(D8/K8,"") | N8: =IFERROR(D8/L8,"") | P8: =IFERROR(O8/D8-1,"") | Q8: =IFERROR(IF(C8="USD",D8/$B$3,D8),"")
A9: UBER | B9: Uber Technologies, Inc. | C9: USD | D9: 71.5293 | F9: =IF(E9="","",D9-E9) | G9: =IFERROR(F9/E9,"") | J9: =IFERROR(D9/H9-1,"") | M9: =IFERROR(D9/K9,"") | N9: =IFERROR(D9/L9,"") | P9: =IFERROR(O9/D9-1,"") | Q9: =IFERROR(IF(C9="USD",D9/$B$3,D9),"")
A11: Yellow = you fill in. Everything black is calculated.
A12: EPS, 52-week range and analyst target are blank by design — see README, Assumptions.
A13: To wire these to a live feed, see README > Making the prices live.

Sheet AMZN
A1: AMZN — Amazon.com, Inc.
A3: 1. POSITION
A4: Ticker | B4: AMZN
A5: Company | B5: Amazon.com, Inc.
A6: Sleeve / pie | B6: Never Sell | C6: Trading 212 pie this sits in
A7: Quote currency | B7: =Prices!$C$7
A8: Shares held | B8: =SUMIFS(Transactions!$K$4:$K$63,Transactions!$B$4:$B$63,$B$4) | C8: calculated from the Transactions log — never typed
A9: Total invested (GBP) | B9: =SUMIFS(Transactions!$O$4:$O$63,Transactions!$B$4:$B$63,$B$4)
A10: Average cost per share (GBP) | B10: =IFERROR($B$9/$B$8,0)
A11: Live price (USD) | B11: =Prices!$D$7 | C11: update on the Prices tab
A12: GBP/USD | B12: =Prices!$B$3
A13: Price per share (GBP) | B13: =Prices!$Q$7
A14: Market value (GBP) | B14: =$B$8*$B$13
A15: Unrealised P/L (GBP) | B15: =$B$14-$B$9
A16: Unrealised P/L % | B16: =IFERROR($B$15/$B$9,0)
A17: Day change (GBP) | B17: =IFERROR($B$8*Prices!$F$7/$B$12,0) | C17: needs Prev close on the Prices tab
A18: Day change % | B18: =IFERROR(Prices!$G$7,0)
A19: % of portfolio | B19: =IFERROR($B$14/Dashboard!$B$6,0) | C19: share of total market value
A20: Realised P/L (GBP) | B20: =SUMIFS(Transactions!$P$4:$P$63,Transactions!$B$4:$B$63,$B$4)
A21: Dividends received (GBP) | B21: =SUMIFS(Dividends!$H$4:$H$43,Dividends!$B$4:$B$43,$B$4)
A22: Total return (GBP) | B22: =$B$15+$B$20+$B$21
A23: Total return % | B23: =IFERROR($B$22/$B$9,0)
A25: 2. VALUATION AND EPS
A26: EPS trailing 12m (USD) | B26: =Prices!$K$7 | C26: enter on the Prices tab — blank by design, I do not invent financials
A27: EPS forward, next FY (USD) | B27: =Prices!$L$7 | C27: consensus, from your broker's research tab
A28: EPS growth, fwd vs TTM | B28: =IFERROR($B$27/$B$26-1,"")
A29: P/E trailing | B29: =Prices!$M$7
A30: P/E forward | B30: =Prices!$N$7
A31: PEG (fwd P/E / growth) | B31: =IFERROR($B$30/($B$28*100),"") | C31: under 1.0 is the classic cheap-for-its-growth marker
A32: Target P/E you would pay | C32: your multiple — this drives fair value below
A33: Fair value (USD) | B33: =IFERROR($B$32*$B$27,"") | C33: target P/E x forward EPS
A34: Fair value (GBP) | B34: =IFERROR($B$33/$B$12,"")
A35: Upside to fair value | B35: =IFERROR($B$33/$B$11-1,"")
A36: Valuation verdict | B36: =IF($B$35="","enter EPS and target P/E",IF($B$35>=0.2,"UNDERVALUED",IF($B$35<=-0.1,"OVERVALUED","FAIRLY VALUED")))
A37: Analyst price target (USD) | B37: =Prices!$O$7
A38: Upside to analyst target | B38: =IFERROR(Prices!$P$7,"")
A39: 52-week high (USD) | B39: =Prices!$H$7
A40: 52-week low (USD) | B40: =Prices!$I$7
A41: % below 52-week high | B41: =IFERROR(Prices!$J$7,"")
A43: 3. SELL DISCIPLINE — the exit plan, decided in advance
...

Sheet MSFT
A1: MSFT — Microsoft Corporation
A3: 1. POSITION
A4: Ticker | B4: MSFT
A5: Company | B5: Microsoft Corporation
A6: Sleeve / pie | B6: Never Sell | C6: Trading 212 pie this sits in
A7: Quote currency | B7: =Prices!$C$8
A8: Shares held | B8: =SUMIFS(Transactions!$K$4:$K$63,Transactions!$B$4:$B$63,$B$4) | C8: calculated from the Transactions log — never typed
A9: Total invested (GBP) | B9: =SUMIFS(Transactions!$O$4:$O$63,Transactions!$B$4:$B$63,$B$4)
A10: Average cost per share (GBP) | B10: =IFERROR($B$9/$B$8,0)
A11: Live price (USD) | B11: =Prices!$D$8 | C11: update on the Prices tab
A12: GBP/USD | B12: =Prices!$B$3
A13: Price per share (GBP) | B13: =Prices!$Q$8
A14: Market value (GBP) | B14: =$B$8*$B$13
A15: Unrealised P/L (GBP) | B15: =$B$14-$B$9
A16: Unrealised P/L % | B16: =IFERROR($B$15/$B$9,0)
A17: Day change (GBP) | B17: =IFERROR($B$8*Prices!$F$8/$B$12,0) | C17: needs Prev close on the Prices tab
A18: Day change % | B18: =IFERROR(Prices!$G$8,0)
A19: % of portfolio | B19: =IFERROR($B$14/Dashboard!$B$6,0) | C19: share of total market value
A20: Realised P/L (GBP) | B20: =SUMIFS(Transactions!$P$4:$P$63,Transactions!$B$4:$B$63,$B$4)
A21: Dividends received (GBP) | B21: =SUMIFS(Dividends!$H$4:$H$43,Dividends!$B$4:$B$43,$B$4)
A22: Total return (GBP) | B22: =$B$15+$B$20+$B$21
A23: Total return % | B23: =IFERROR($B$22/$B$9,0)
A25: 2. VALUATION AND EPS
A26: EPS trailing 12m (USD) | B26: =Prices!$K$8 | C26: enter on the Prices tab — blank by design, I do not invent financials
A27: EPS forward, next FY (USD) | B27: =Prices!$L$8 | C27: consensus, from your broker's research tab
A28: EPS growth, fwd vs TTM | B28: =IFERROR($B$27/$B$26-1,"")
A29: P/E trailing | B29: =Prices!$M$8
A30: P/E forward | B30: =Prices!$N$8
A31: PEG (fwd P/E / growth) | B31: =IFERROR($B$30/($B$28*100),"") | C31: under 1.0 is the classic cheap-for-its-growth marker
A32: Target P/E you would pay | C32: your multiple — this drives fair value below
A33: Fair value (USD) | B33: =IFERROR($B$32*$B$27,"") | C33: target P/E x forward EPS
A34: Fair value (GBP) | B34: =IFERROR($B$33/$B$12,"")
A35: Upside to fair value | B35: =IFERROR($B$33/$B$11-1,"")
A36: Valuation verdict | B36: =IF($B$35="","enter EPS and target P/E",IF($B$35>=0.2,"UNDERVALUED",IF($B$35<=-0.1,"OVERVALUED","FAIRLY VALUED")))
A37: Analyst price target (USD) | B37: =Prices!$O$8
A38: Upside to analyst target | B38: =IFERROR(Prices!$P$8,"")
A39: 52-week high (USD) | B39: =Prices!$H$8
A40: 52-week low (USD) | B40: =Prices!$I$8
A41: % below 52-week high | B41: =IFERROR(Prices!$J$8,"")
A43: 3. SELL DISCIPLINE — the exit plan, decided in advance
...

Sheet UBER
A1: UBER — Uber Technologies, Inc.
A3: 1. POSITION
A4: Ticker | B4: UBER
A5: Company | B5: Uber Technologies, Inc.
A6: Sleeve / pie | B6: Never Sell | C6: Trading 212 pie this sits in
A7: Quote currency | B7: =Prices!$C$9
A8: Shares held | B8: =SUMIFS(Transactions!$K$4:$K$63,Transactions!$B$4:$B$63,$B$4) | C8: calculated from the Transactions log — never typed
A9: Total invested (GBP) | B9: =SUMIFS(Transactions!$O$4:$O$63,Transactions!$B$4:$B$63,$B$4)
A10: Average cost per share (GBP) | B10: =IFERROR($B$9/$B$8,0)
A11: Live price (USD) | B11: =Prices!$D$9 | C11: update on the Prices tab
A12: GBP/USD | B12: =Prices!$B$3
A13: Price per share (GBP) | B13: =Prices!$Q$9
A14: Market value (GBP) | B14: =$B$8*$B$13
A15: Unrealised P/L (GBP) | B15: =$B$14-$B$9
A16: Unrealised P/L % | B16: =IFERROR($B$15/$B$9,0)
A17: Day change (GBP) | B17: =IFERROR($B$8*Prices!$F$9/$B$12,0) | C17: needs Prev close on the Prices tab
A18: Day change % | B18: =IFERROR(Prices!$G$9,0)
A19: % of portfolio | B19: =IFERROR($B$14/Dashboard!$B$6,0) | C19: share of total market value
A20: Realised P/L (GBP) | B20: =SUMIFS(Transactions!$P$4:$P$63,Transactions!$B$4:$B$63,$B$4)
A21: Dividends received (GBP) | B21: =SUMIFS(Dividends!$H$4:$H$43,Dividends!$B$4:$B$43,$B$4)
A22: Total return (GBP) | B22: =$B$15+$B$20+$B$21
A23: Total return % | B23: =IFERROR($B$22/$B$9,0)
A25: 2. VALUATION AND EPS
A26: EPS trailing 12m (USD) | B26: =Prices!$K$9 | C26: enter on the Prices tab — blank by design, I do not invent financials
A27: EPS forward, next FY (USD) | B27: =Prices!$L$9 | C27: consensus, from your broker's research tab
A28: EPS growth, fwd vs TTM | B28: =IFERROR($B$27/$B$26-1,"")
A29: P/E trailing | B29: =Prices!$M$9
A30: P/E forward | B30: =Prices!$N$9
A31: PEG (fwd P/E / growth) | B31: =IFERROR($B$30/($B$28*100),"") | C31: under 1.0 is the classic cheap-for-its-growth marker
A32: Target P/E you would pay | C32: your multiple — this drives fair value below
A33: Fair value (USD) | B33: =IFERROR($B$32*$B$27,"") | C33: target P/E x forward EPS
A34: Fair value (GBP) | B34: =IFERROR($B$33/$B$12,"")
A35: Upside to fair value | B35: =IFERROR($B$33/$B$11-1,"")
A36: Valuation verdict | B36: =IF($B$35="","enter EPS and target P/E",IF($B$35>=0.2,"UNDERVALUED",IF($B$35<=-0.1,"OVERVALUED","FAIRLY VALUED")))
A37: Analyst price target (USD) | B37: =Prices!$O$9
A38: Upside to analyst target | B38: =IFERROR(Prices!$P$9,"")
A39: 52-week high (USD) | B39: =Prices!$H$9
A40: 52-week low (USD) | B40: =Prices!$I$9
A41: % below 52-week high | B41: =IFERROR(Prices!$J$9,"")
A43: 3. SELL DISCIPLINE — the exit plan, decided in advance
...

Sheet Transactions
A1: MASTER TRADE LOG — every buy and sell goes here once
A2: Shares held and average cost on every holding tab are calculated from this sheet. Add new trades in the next empty row and keep the formulas in columns G to P.
A3: Date | B3: Ticker | C3: Type | D3: Shares | E3: Price/share (native) | F3: FX (GBP/USD) | G3: Price/share (GBP) | H3: Gross (GBP) | I3: Fees (GBP) | J3: Net cash (GBP) | K3: Signed shares | L3: Shares before | M3: Cost basis before | N3: Avg cost before | O3: Cost basis impact | P3: Realised P/L (GBP) | Q3: Notes
A4: 2026-08-04 | B4: AMZN | C4: BUY | D4: 66.0103 | E4: 248.67002 | F4: 1.34499 | G4: =IF($B4="","",IFERROR($E4/$F4,0)) | H4: =IF($B4="","",$D4*$G4) | I4: 0 | J4: =IF($B4="","",IF($C4="BUY",$H4+$I4,$H4-$I4)) | K4: =IF($B4="","",IF($C4="BUY",$D4,-$D4)) | L4: =IF($B4="","",0) | M4: =IF($B4="","",0) | N4: =IF($B4="","",IFERROR($M4/$L4,0)) | O4: =IF($B4="","",IF($C4="BUY",$J4,-$D4*$N4)) | P4: =IF($B4="","",IF($C4="SELL",$J4-$D4*$N4,0)) | Q4: Opening position from Trading 212 Never Sell pie export, 4 Aug 2026. Replace with your real trade history when you have it.
A5: 2026-08-04 | B5: MSFT | C5: BUY | D5: 20.4311 | E5: 381.84797 | F5: 1.34499 | G5: =IF($B5="","",IFERROR($E5/$F5,0)) | H5: =IF($B5="","",$D5*$G5) | I5: 0 | J5: =IF($B5="","",IF($C5="BUY",$H5+$I5,$H5-$I5)) | K5: =IF($B5="","",IF($C5="BUY",$D5,-$D5)) | L5: =IF($B5="","",SUMIFS($K$4:$K4,$B$4:$B4,$B5)) | M5: =IF($B5="","",SUMIFS($O$4:$O4,$B$4:$B4,$B5)) | N5: =IF($B5="","",IFERROR($M5/$L5,0)) | O5: =IF($B5="","",IF($C5="BUY",$J5,-$D5*$N5)) | P5: =IF($B5="","",IF($C5="SELL",$J5-$D5*$N5,0)) | Q5: Opening position from Trading 212 Never Sell pie export, 4 Aug 2026. Replace with your real trade history when you have it.
A6: 2026-08-04 | B6: UBER | C6: BUY | D6: 109.6538 | E6: 68.789715 | F6: 1.34499 | G6: =IF($B6="","",IFERROR($E6/$F6,0)) | H6: =IF($B6="","",$D6*$G6) | I6: 0 | J6: =IF($B6="","",IF($C6="BUY",$H6+$I6,$H6-$I6)) | K6: =IF($B6="","",IF($C6="BUY",$D6,-$D6)) | L6: =IF($B6="","",SUMIFS($K$4:$K5,$B$4:$B5,$B6)) | M6: =IF($B6="","",SUMIFS($O$4:$O5,$B$4:$B5,$B6)) | N6: =IF($B6="","",IFERROR($M6/$L6,0)) | O6: =IF($B6="","",IF($C6="BUY",$J6,-$D6*$N6)) | P6: =IF($B6="","",IF($C6="SELL",$J6-$D6*$N6,0)) | Q6: Opening position from Trading 212 Never Sell pie export, 4 Aug 2026. Replace with your real trade history when you have it.
G7: =IF($B7="","",IFERROR($E7/$F7,0)) | H7: =IF($B7="","",$D7*$G7) | J7: =IF($B7="","",IF($C7="BUY",$H7+$I7,$H7-$I7)) | K7: =IF($B7="","",IF($C7="BUY",$D7,-$D7)) | L7: =IF($B7="","",SUMIFS($K$4:$K6,$B$4:$B6,$B7)) | M7: =IF($B7="","",SUMIFS($O$4:$O6,$B$4:$B6,$B7)) | N7: =IF($B7="","",IFERROR($M7/$L7,0)) | O7: =IF($B7="","",IF($C7="BUY",$J7,-$D7*$N7)) | P7: =IF($B7="","",IF($C7="SELL",$J7-$D7*$N7,0))
G8: =IF($B8="","",IFERROR($E8/$F8,0)) | H8: =IF($B8="","",$D8*$G8) | J8: =IF($B8="","",IF($C8="BUY",$H8+$I8,$H8-$I8)) | K8: =IF($B8="","",IF($C8="BUY",$D8,-$D8)) | L8: =IF($B8="","",SUMIFS($K$4:$K7,$B$4:$B7,$B8)) | M8: =IF($B8="","",SUMIFS($O$4:$O7,$B$4:$B7,$B8)) | N8: =IF($B8="","",IFERROR($M8/$L8,0)) | O8: =IF($B8="","",IF($C8="BUY",$J8,-$D8*$N8)) | P8: =IF($B8="","",IF($C8="SELL",$J8-$D8*$N8,0))
G9: =IF($B9="","",IFERROR($E9/$F9,0)) | H9: =IF($B9="","",$D9*$G9) | J9: =IF($B9="","",IF($C9="BUY",$H9+$I9,$H9-$I9)) | K9: =IF($B9="","",IF($C9="BUY",$D9,-$D9)) | L9: =IF($B9="","",SUMIFS($K$4:$K8,$B$4:$B8,$B9)) | M9: =IF($B9="","",SUMIFS($O$4:$O8,$B$4:$B8,$B9)) | N9: =IF($B9="","",IFERROR($M9/$L9,0)) | O9: =IF($B9="","",IF($C9="BUY",$J9,-$D9*$N9)) | P9: =IF($B9="","",IF($C9="SELL",$J9-$D9*$N9,0))
G10: =IF($B10="","",IFERROR($E10/$F10,0)) | H10: =IF($B10="","",$D10*$G10) | J10: =IF($B10="","",IF($C10="BUY",$H10+$I10,$H10-$I10)) | K10: =IF($B10="","",IF($C10="BUY",$D10,-$D10)) | L10: =IF($B10="","",SUMIFS($K$4:$K9,$B$4:$B9,$B10)) | M10: =IF($B10="","",SUMIFS($O$4:$O9,$B$4:$B9,$B10)) | N10: =IF($B10="","",IFERROR($M10/$L10,0)) | O10: =IF($B10="","",IF($C10="BUY",$J10,-$D10*$N10)) | P10: =IF($B10="","",IF($C10="SELL",$J10-$D10*$N10,0))
G11: =IF($B11="","",IFERROR($E11/$F11,0)) | H11: =IF($B11="","",$D11*$G11) | J11: =IF($B11="","",IF($C11="BUY",$H11+$I11,$H11-$I11)) | K11: =IF($B11="","",IF($C11="BUY",$D11,-$D11)) | L11: =IF($B11="","",SUMIFS($K$4:$K10,$B$4:$B10,$B11)) | M11: =IF($B11="","",SUMIFS($O$4:$O10,$B$4:$B10,$B11)) | N11: =IF($B11="","",IFERROR($M11/$L11,0)) | O11: =IF($B11="","",IF($C11="BUY",$J11,-$D11*$N11)) | P11: =IF($B11="","",IF($C11="SELL",$J11-$D11*$N11,0))
G12: =IF($B12="","",IFERROR($E12/$F12,0)) | H12: =IF($B12="","",$D12*$G12) | J12: =IF($B12="","",IF($C12="BUY",$H12+$I12,$H12-$I12)) | K12: =IF($B12="","",IF($C12="BUY",$D12,-$D12)) | L12: =IF($B12="","",SUMIFS($K$4:$K11,$B$4:$B11,$B12)) | M12: =IF($B12="","",SUMIFS($O$4:$O11,$B$4:$B11,$B12)) | N12: =IF($B12="","",IFERROR($M12/$L12,0)) | O12: =IF($B12="","",IF($C12="BUY",$J12,-$D12*$N12)) | P12: =IF($B12="","",IF($C12="SELL",$J12-$D12*$N12,0))
G13: =IF($B13="","",IFERROR($E13/$F13,0)) | H13: =IF($B13="","",$D13*$G13) | J13: =IF($B13="","",IF($C13="BUY",$H13+$I13,$H13-$I13)) | K13: =IF($B13="","",IF($C13="BUY",$D13,-$D13)) | L13: =IF($B13="","",SUMIFS($K$4:$K12,$B$4:$B12,$B13)) | M13: =IF($B13="","",SUMIFS($O$4:$O12,$B$4:$B12,$B13)) | N13: =IF($B13="","",IFERROR($M13/$L13,0)) | O13: =IF($B13="","",IF($C13="BUY",$J13,-$D13*$N13)) | P13: =IF($B13="","",IF($C13="SELL",$J13-$D13*$N13,0))
G14: =IF($B14="","",IFERROR($E14/$F14,0)) | H14: =IF($B14="","",$D14*$G14) | J14: =IF($B14="","",IF($C14="BUY",$H14+$I14,$H14-$I14)) | K14: =IF($B14="","",IF($C14="BUY",$D14,-$D14)) | L14: =IF($B14="","",SUMIFS($K$4:$K13,$B$4:$B13,$B14)) | M14: =IF($B14="","",SUMIFS($O$4:$O13,$B$4:$B13,$B14)) | N14: =IF($B14="","",IFERROR($M14/$L14,0)) | O14: =IF($B14="","",IF($C14="BUY",$J14,-$D14*$N14)) | P14: =IF($B14="","",IF($C14="SELL",$J14-$D14*$N14,0))
G15: =IF($B15="","",IFERROR($E15/$F15,0)) | H15: =IF($B15="","",$D15*$G15) | J15: =IF($B15="","",IF($C15="BUY",$H15+$I15,$H15-$I15)) | K15: =IF($B15="","",IF($C15="BUY",$D15,-$D15)) | L15: =IF($B15="","",SUMIFS($K$4:$K14,$B$4:$B14,$B15)) | M15: =IF($B15="","",SUMIFS($O$4:$O14,$B$4:$B14,$B15)) | N15: =IF($B15="","",IFERROR($M15/$L15,0)) | O15: =IF($B15="","",IF($C15="BUY",$J15,-$D15*$N15)) | P15: =IF($B15="","",IF($C15="SELL",$J15-$D15*$N15,0))
G16: =IF($B16="","",IFERROR($E16/$F16,0)) | H16: =IF($B16="","",$D16*$G16) | J16: =IF($B16="","",IF($C16="BUY",$H16+$I16,$H16-$I16)) | K16: =IF($B16="","",IF($C16="BUY",$D16,-$D16)) | L16: =IF($B16="","",SUMIFS($K$4:$K15,$B$4:$B15,$B16)) | M16: =IF($B16="","",SUMIFS($O$4:$O15,$B$4:$B15,$B16)) | N16: =IF($B16="","",IFERROR($M16/$L16,0)) | O16: =IF($B16="","",IF($C16="BUY",$J16,-$D16*$N16)) | P16: =IF($B16="","",IF($C16="SELL",$J16-$D16*$N16,0))
G17: =IF($B17="","",IFERROR($E17/$F17,0)) | H17: =IF($B17="","",$D17*$G17) | J17: =IF($B17="","",IF($C17="BUY",$H17+$I17,$H17-$I17)) | K17: =IF($B17="","",IF($C17="BUY",$D17,-$D17)) | L17: =IF($B17="","",SUMIFS($K$4:$K16,$B$4:$B16,$B17)) | M17: =IF($B17="","",SUMIFS($O$4:$O16,$B$4:$B16,$B17)) | N17: =IF($B17="","",IFERROR($M17/$L17,0)) | O17: =IF($B17="","",IF($C17="BUY",$J17,-$D17*$N17)) | P17: =IF($B17="","",IF($C17="SELL",$J17-$D17*$N17,0))
G18: =IF($B18="","",IFERROR($E18/$F18,0)) | H18: =IF($B18="","",$D18*$G18) | J18: =IF($B18="","",IF($C18="BUY",$H18+$I18,$H18-$I18)) | K18: =IF($B18="","",IF($C18="BUY",$D18,-$D18)) | L18: =IF($B18="","",SUMIFS($K$4:$K17,$B$4:$B17,$B18)) | M18: =IF($B18="","",SUMIFS($O$4:$O17,$B$4:$B17,$B18)) | N18: =IF($B18="","",IFERROR($M18/$L18,0)) | O18: =IF($B18="","",IF($C18="BUY",$J18,-$D18*$N18)) | P18: =IF($B18="","",IF($C18="SELL",$J18-$D18*$N18,0))
... G63: =IF($B63="","",IFERROR($E63/$F63,0)) | H63: =IF($B63="","",$D63*$G63) | J63: =IF($B63="","",IF($C63="BUY",$H63+$I63,$H63-$I63)) | K63: =IF($B63="","",IF($C63="BUY",$D63,-$D63)) | L63: =IF($B63="","",SUMIFS($K$4:$K62,$B$4:$B62,$B63)) | M63: =IF($B63="","",SUMIFS($O$4:$O62,$B$4:$B62,$B63)) | N63: =IF($B63="","",IFERROR($M63/$L63,0)) | O63: =IF($B63="","",IF($C63="BUY",$J63,-$D63*$N63)) | P63: =IF($B63="","",IF($C63="SELL",$J63-$D63*$N63,0))
A65: Average-cost accounting: a SELL is booked against the average cost of the shares held before it, and the difference lands in Realised P/L.
A66: For a GBP-quoted holding (LGEN, BA, SHEL) put the price in pounds in column E and set FX to 1.
A67: Need more than 60 trades? Copy the last row down — every formula is relative.

Sheet Dividends
A1: DIVIDEND LOG — feeds the income block on each holding tab
A2: Log each payment as it lands. Net GBP is what actually hit the account.
A3: Date | B3: Ticker | C3: Shares at pay date | D3: Gross (native) | E3: FX (GBP/USD) | F3: Gross (GBP) | G3: Withholding tax (GBP) | H3: Net (GBP) | I3: Notes
F4: =IF($B4="","",IFERROR($D4/$E4,0)) | H4: =IF($B4="","",$F4-$G4)
F5: =IF($B5="","",IFERROR($D5/$E5,0)) | H5: =IF($B5="","",$F5-$G5)
F6: =IF($B6="","",IFERROR($D6/$E6,0)) | H6: =IF($B6="","",$F6-$G6)
F7: =IF($B7="","",IFERROR($D7/$E7,0)) | H7: =IF($B7="","",$F7-$G7)
F8: =IF($B8="","",IFERROR($D8/$E8,0)) | H8: =IF($B8="","",$F8-$G8)
F9: =IF($B9="","",IFERROR($D9/$E9,0)) | H9: =IF($B9="","",$F9-$G9)
F10: =IF($B10="","",IFERROR($D10/$E10,0)) | H10: =IF($B10="","",$F10-$G10)
F11: =IF($B11="","",IFERROR($D11/$E11,0)) | H11: =IF($B11="","",$F11-$G11)
F12: =IF($B12="","",IFERROR($D12/$E12,0)) | H12: =IF($B12="","",$F12-$G12)
F13: =IF($B13="","",IFERROR($D13/$E13,0)) | H13: =IF($B13="","",$F13-$G13)
F14: =IF($B14="","",IFERROR($D14/$E14,0)) | H14: =IF($B14="","",$F14-$G14)
F15: =IF($B15="","",IFERROR($D15/$E15,0)) | H15: =IF($B15="","",$F15-$G15)
... F43: =IF($B43="","",IFERROR($D43/$E43,0)) | H43: =IF($B43="","",$F43-$G43)
A45: US dividends in a UK ISA are normally taxed at 15% at source with a W-8BEN on file. Put that amount in column G.
A46: Of AMZN, MSFT and UBER, only MSFT currently pays a dividend.

Sheet Sell_Rules
A1: DEFAULT SELL RULES — every holding tab inherits these
A3: TRIGGER LEVELS
A4: Rule | B4: Level | C4: What it means
A5: Take-profit target (% above avg cost) | B5: 0.5 | C5: Full exit candidate. Price >= avg cost x 1.50.
A6: Trim level 1 (% above avg cost) | B6: 0.25 | C6: First trim. Take some off the table, let the rest run.
A7: Trim level 2 (% above avg cost) | B7: 0.4 | C7: Second trim, closer to the full target.
A8: Stop loss (% below avg cost) | B8: 0.2 | C8: Hard exit. Price <= avg cost x 0.80.
A9: Trailing stop (% below 52-week high) | B9: 0.25 | C9: Protects a run-up. Price <= 52w high x 0.75.
A11: These are placeholders, not advice — set them to your own discipline.
A12: A holding tab can override any level: just type a number over the green link.
A14: SIGNAL PRIORITY — the order each holding tab tests
A15: 1. No position -> NO POSITION
A16: 2. Manual sell price set and reached -> SELL - MANUAL TARGET
A17: 3. Price at or below stop loss -> SELL - STOP LOSS
A18: 4. Price at or above take-profit -> SELL - TARGET HIT
A19: 5. Price at or above trim 2 -> TRIM 2
A20: 6. Price at or above trim 1 -> TRIM 1
A21: 7. Price at or below trailing stop -> REVIEW - TRAILING STOP
A22: 8. Otherwise -> HOLD
A24: Stop loss is tested before take-profit so a crash is never masked by a stale target.
